<mujoco model='bombmodel'>
    <compiler angle='degree' coordinate='local' inertiafromgeom='true'/>
        <worldbody>
            <body name='apple' pos='0 0 2'>
                <joint name='ballx' type='slide' axis='1 0 0' pos='0 0 2' limited='false' damping='0.1' armature='0' stiffness='0'/>
                <joint name='bally' type='slide' axis='0 1 0' pos='0 0 2' limited='false' damping='0.1' armature='0' stiffness='0'/>
                <geom type='sphere' size='0.5' rgba='0.22 0.60 0.18 1'/>
            </body>
        </worldbody>
</mujoco>
